Workbook

Sheet Assumptions
A1: Sales Executives | B1: 50
A2: Deals per Exec | B2: 8 | D2: Scenario Manager | E2: Base Case | G2: Scenario | H2: Growth % | I2: Why
A3: Avg Deal Size | B3: 3000 | D3: Monthly Growth % | E3: 0.05 | G3: Worst | H3: 0.03 | I3: Demand slowdown, fewer deals
A4: Monthly Growth % | B4: {=XLOOKUP(Revenue!B1, G3:G5, H3:H5)} -> 0.05 | D4: Marketing % | E4: 0.1 | G4: Base | H4: 0.05 | I4: Your original assumption
A5: Marketing % | B5: 0.1 | D5: Admin Cost | E5: =B6 -> 50000 | G5: Best | H5: 0.07 | I5: Strong demand, better pipeline
A6: Admin Cost | B6: 50000 | D6: Rent & Tech | E6: =B7 -> 30000
A7: Rent & Tech | B7: 30000 | D7: Sales Salary | E7: =B8 -> 1200 | G7: IMP Note:- The model includes scenario dropdowns (Worst, Base, Best) in Revenue Sheet and month selectors Drop down in Region_BU sheets that dynamically update Revenue, Region Allocation, BU Allocation, P&L, Cash Flow and Balance Sheet.
A8: Sales Salary | B8: 1200 | D8: Regional Head Salary | E8: =B9 -> 3000
A9: Regional Head Salary | B9: 3000 | D9: Other Employee Salary | E9: =B10 -> 1000
A10: Other Employee Salary | B10: 1000 | D10: Receivable Days | E10: =B22 -> 45
A11: Total Employees | B11: 1000 | D11: Payable Days | E11: =B23 -> 30
A12: Regional Head | B12: 10 | D12: Tax Rate | E12: 0.25
D13: Depreciation Rate | E13: 0.1
A14: Assumption based on Actual Revenue are from Rand Between Formula | B14: C2*(1+RANDBETWEEN(-10,10)/100) | D14: Salary Increment % | E14: 0.08
A15: Region | B15: % Allocation | D15: Total Deals | E15: =B1*B2 -> 400
A16: Region1 | B16: 0.25 | D16: Avg Deal Size | E16: 3000
A17: Region2 | B17: 0.2 | D17: Expected Monthly Revenue | E17: =E15*E16 -> 1200000
A18: Region3 | B18: 0.18
A19: Region4 | B19: 0.22 | D19: Total Salary Cost | E19: {=SUM(B8:B12*1000)} -> 6210000
A20: Region5 | B20: 0.15 | D20: Total Admin Cost | E20: =B6 -> 50000
A21: Total | B21: =SUM(B16:B20) -> 1 | D21: Total Rent & Tech | E21: =B7 -> 30000
A22: Receivable Days | B22: 45 | D22: Total Marketing Cost | E22: =B5*E17 -> 120000
A23: Payable Days | B23: 30
A24: Tax Rate | B24: 0.25
A25: Depreciation Rate | B25: 0.1
A26: Salary Increment % | B26: 0.08
A27: Scenario | B27: Base
A30: Department | B30: Headcount | C30: Salary
A31: Sales Executives | B31: 50 | C31: =B8 -> 1200
A32: Regional Heads | B32: 10 | C32: =B9 -> 3000
A33: Delivery / Tech | B33: 800 | C33: =B10 -> 1000
A34: HR | B34: 50 | C34: =B10 -> 1000
A35: Finance | B35: 40 | C35: =B10 -> 1000
A36: Admin | B36: 50 | C36: =B10 -> 1000
A37: Total headcount | B37: =SUM(B31:B36) -> 1000
A39: Headcount Check | B39: =IF(B37=B11,"OK","ERROR") -> OK
A41: BU Allocation:
A42: BU1 = 20%
A43: BU2 = 20%
A44: BU3 = 20%
...

Sheet Revenue
A1: Scenario: | B1: Base
A2: Months | B2: JAN | C2: FEB | D2: MAR | E2: APR | F2: MAY | G2: JUN | H2: JUL | I2: AUG | J2: SEP | K2: OCT | L2: NOV | M2: DEC
A3: Revenue | B3: =Assumptions!B1*Assumptions!B2*Assumptions!B3 -> 1200000 | C3: =B3*(1+Assumptions!$B$4) -> 1260000 | D3: =C3*(1+Assumptions!$B$4) -> 1323000 | E3: =D3*(1+Assumptions!$B$4) -> 1389150 | F3: =E3*(1+Assumptions!$B$4) -> 1458607.5 | G3: =F3*(1+Assumptions!$B$4) -> 1531537.9 | H3: =G3*(1+Assumptions!$B$4) -> 1608114.8 | I3: =H3*(1+Assumptions!$B$4) -> 1688520.5 | J3: =I3*(1+Assumptions!$B$4) -> 1772946.5 | ... M3: =L3*(1+Assumptions!$B$4) -> 2052407.2
A5: Region Revenue Allocation
A6: Region | B6: JAN | C6: FEB | D6: MAR | E6: APR | F6: MAY | G6: JUN | H6: JUL | I6: AUG | J6: SEP | K6: OCT | L6: NOV | M6: DEC
A7: Region1 | B7: =B$3*Assumptions!$B$16 -> 300000 | C7: =C$3*Assumptions!$B$16 -> 315000 | D7: =D$3*Assumptions!$B$16 -> 330750 | E7: =E$3*Assumptions!$B$16 -> 347287.5 | F7: =F$3*Assumptions!$B$16 -> 364651.88 | G7: =G$3*Assumptions!$B$16 -> 382884.47 | H7: =H$3*Assumptions!$B$16 -> 402028.69 | I7: =I$3*Assumptions!$B$16 -> 422130.13 | ... M7: =M$3*Assumptions!$B$16 -> 513101.81
A8: Region2 | B8: =B$3*Assumptions!$B$17 -> 240000 | C8: =C$3*Assumptions!$B$17 -> 252000 | D8: =D$3*Assumptions!$B$17 -> 264600 | E8: =E$3*Assumptions!$B$17 -> 277830 | F8: =F$3*Assumptions!$B$17 -> 291721.5 | G8: =G$3*Assumptions!$B$17 -> 306307.58 | H8: =H$3*Assumptions!$B$17 -> 321622.95 | I8: =I$3*Assumptions!$B$17 -> 337704.1 | ... M8: =M$3*Assumptions!$B$17 -> 410481.45
A9: Region3 | B9: =B$3*Assumptions!$B$18 -> 216000 | C9: =C$3*Assumptions!$B$18 -> 226800 | D9: =D$3*Assumptions!$B$18 -> 238140 | E9: =E$3*Assumptions!$B$18 -> 250047 | F9: =F$3*Assumptions!$B$18 -> 262549.35 | G9: =G$3*Assumptions!$B$18 -> 275676.82 | H9: =H$3*Assumptions!$B$18 -> 289460.66 | I9: =I$3*Assumptions!$B$18 -> 303933.69 | ... M9: =M$3*Assumptions!$B$18 -> 369433.3
A10: Region4 | B10: =B$3*Assumptions!$B$19 -> 264000 | C10: =C$3*Assumptions!$B$19 -> 277200 | D10: =D$3*Assumptions!$B$19 -> 291060 | E10: =E$3*Assumptions!$B$19 -> 305613 | F10: =F$3*Assumptions!$B$19 -> 320893.65 | G10: =G$3*Assumptions!$B$19 -> 336938.33 | H10: =H$3*Assumptions!$B$19 -> 353785.25 | I10: =I$3*Assumptions!$B$19 -> 371474.51 | ... M10: =M$3*Assumptions!$B$19 -> 451529.59
A11: Region5 | B11: =B$3*Assumptions!$B$20 -> 180000 | C11: =C$3*Assumptions!$B$20 -> 189000 | D11: =D$3*Assumptions!$B$20 -> 198450 | E11: =E$3*Assumptions!$B$20 -> 208372.5 | F11: =F$3*Assumptions!$B$20 -> 218791.12 | G11: =G$3*Assumptions!$B$20 -> 229730.68 | H11: =H$3*Assumptions!$B$20 -> 241217.22 | I11: =I$3*Assumptions!$B$20 -> 253278.08 | ... M11: =M$3*Assumptions!$B$20 -> 307861.08
A12: Total Check | B12: =SUM(B7:B11) -> 1200000 | C12: =SUM(C7:C11) -> 1260000 | D12: =SUM(D7:D11) -> 1323000 | E12: =SUM(E7:E11) -> 1389150 | F12: =SUM(F7:F11) -> 1458607.5 | G12: =SUM(G7:G11) -> 1531537.9 | H12: =SUM(H7:H11) -> 1608114.8 | I12: =SUM(I7:I11) -> 1688520.5 | ... M12: =SUM(M7:M11) -> 2052407.2
A13: Validation | B13: =IF(B12=B3,"OK","ERROR") -> OK | C13: =IF(C12=C3,"OK","ERROR") -> OK | D13: =IF(D12=D3,"OK","ERROR") -> OK | E13: =IF(E12=E3,"OK","ERROR") -> OK | F13: =IF(F12=F3,"OK","ERROR") -> OK | G13: =IF(G12=G3,"OK","ERROR") -> OK | H13: =IF(H12=H3,"OK","ERROR") -> OK | I13: =IF(I12=I3,"OK","ERROR") -> OK | ... M13: =IF(M12=M3,"OK","ERROR") -> OK
A16: Months | B16: JAN | C16: FEB | D16: MAR | E16: APR | F16: MAY | G16: JUN | H16: JUL | I16: AUG | J16: SEP | K16: OCT | L16: NOV | M16: DEC
A17: BU1 | B17: =B3*20% -> 240000 | C17: =C3*20% -> 252000 | D17: =D3*20% -> 264600 | E17: =E3*20% -> 277830 | F17: =F3*20% -> 291721.5 | G17: =G3*20% -> 306307.58 | H17: =H3*20% -> 321622.95 | I17: =I3*20% -> 337704.1 | ... M17: =M3*20% -> 410481.45
A18: BU2 | B18: =B3*20% -> 240000 | C18: =C3*20% -> 252000 | D18: =D3*20% -> 264600 | E18: =E3*20% -> 277830 | F18: =F3*20% -> 291721.5 | G18: =G3*20% -> 306307.58 | H18: =H3*20% -> 321622.95 | I18: =I3*20% -> 337704.1 | ... M18: =M3*20% -> 410481.45
A19: BU3 | B19: =B3*20% -> 240000 | C19: =C3*20% -> 252000 | D19: =D3*20% -> 264600 | E19: =E3*20% -> 277830 | F19: =F3*20% -> 291721.5 | G19: =G3*20% -> 306307.58 | H19: =H3*20% -> 321622.95 | I19: =I3*20% -> 337704.1 | ... M19: =M3*20% -> 410481.45
A20: BU4 | B20: =B3*20% -> 240000 | C20: =C3*20% -> 252000 | D20: =D3*20% -> 264600 | E20: =E3*20% -> 277830 | F20: =F3*20% -> 291721.5 | G20: =G3*20% -> 306307.58 | H20: =H3*20% -> 321622.95 | I20: =I3*20% -> 337704.1 | ... M20: =M3*20% -> 410481.45
A21: BU5 | B21: =B3*20% -> 240000 | C21: =C3*20% -> 252000 | D21: =D3*20% -> 264600 | E21: =E3*20% -> 277830 | F21: =F3*20% -> 291721.5 | G21: =G3*20% -> 306307.58 | H21: =H3*20% -> 321622.95 | I21: =I3*20% -> 337704.1 | ... M21: =M3*20% -> 410481.45

Sheet Costs
A1: Months | B1: JAN | C1: FEB | D1: MAR | E1: APR | F1: MAY | G1: JUN | H1: JUL | I1: AUG | J1: SEP | K1: OCT | L1: NOV | M1: DEC | N1: Total Cost Break Down (Yearly)
A2: Salary Cost | B2: =(Assumptions!$B$1*Assumptions!$B$8) +(Assumptions!$B$12*Assumptions!$B$9) +((Assumptions!$B$11-(Assumptions!$B$1+Assumptions!$B$12))*Assumptions!$B$10) -> 1030000 | C2: =(Assumptions!$B$1*Assumptions!$B$8) +(Assumptions!$B$12*Assumptions!$B$9) +((Assumptions!$B$11-(Assumptions!$B$1+Assumptions!$B$12))*Assumptions!$B$10) -> 1030000 | D2: =(Assumptions!$B$1*Assumptions!$B$8) +(Assumptions!$B$12*Assumptions!$B$9) +((Assumptions!$B$11-(Assumptions!$B$1+Assumptions!$B$12))*Assumptions!$B$10) -> 1030000 | E2: =(Assumptions!$B$1*Assumptions!$B$8) +(Assumptions!$B$12*Assumptions!$B$9) +((Assumptions!$B$11-(Assumptions!$B$1+Assumptions!$B$12))*Assumptions!$B$10) -> 1030000 | F2: =(Assumptions!$B$1*Assumptions!$B$8) +(Assumptions!$B$12*Assumptions!$B$9) +((Assumptions!$B$11-(Assumptions!$B$1+Assumptions!$B$12))*Assumptions!$B$10) -> 1030000 | G2: =(Assumptions!$B$1*Assumptions!$B$8) +(Assumptions!$B$12*Assumptions!$B$9) +((Assumptions!$B$11-(Assumptions!$B$1+Assumptions!$B$12))*Assumptions!$B$10) -> 1030000 | H2: =(Assumptions!$B$1*Assumptions!$B$8) +(Assumptions!$B$12*Assumptions!$B$9) +((Assumptions!$B$11-(Assumptions!$B$1+Assumptions!$B$12))*Assumptions!$B$10) -> 1030000 | I2: =(Assumptions!$B$1*Assumptions!$B$8) +(Assumptions!$B$12*Assumptions!$B$9) +((Assumptions!$B$11-(Assumptions!$B$1+Assumptions!$B$12))*Assumptions!$B$10) -> 1030000 | ... M2: =(Assumptions!$B$1*Assumptions!$B$8) +(Assumptions!$B$12*Assumptions!$B$9) +((Assumptions!$B$11-(Assumptions!$B$1+Assumptions!$B$12))*Assumptions!$B$10) -> 1030000 | N2: =SUM(B2:M2) -> 12360000
A3: Marketing | B3: =Revenue!B3*Assumptions!$B$5 -> 120000 | C3: =Revenue!C3*Assumptions!$B$5 -> 126000 | D3: =Revenue!D3*Assumptions!$B$5 -> 132300 | E3: =Revenue!E3*Assumptions!$B$5 -> 138915 | F3: =Revenue!F3*Assumptions!$B$5 -> 145860.75 | G3: =Revenue!G3*Assumptions!$B$5 -> 153153.79 | H3: =Revenue!H3*Assumptions!$B$5 -> 160811.48 | I3: =Revenue!I3*Assumptions!$B$5 -> 168852.05 | ... M3: =Revenue!M3*Assumptions!$B$5 -> 205240.72 | N3: =SUM(B3:M3) -> 1910055.2
A4: Admin | B4: =Assumptions!$B$6 -> 50000 | C4: =Assumptions!$B$6 -> 50000 | D4: =Assumptions!$B$6 -> 50000 | E4: =Assumptions!$B$6 -> 50000 | F4: =Assumptions!$B$6 -> 50000 | G4: =Assumptions!$B$6 -> 50000 | H4: =Assumptions!$B$6 -> 50000 | I4: =Assumptions!$B$6 -> 50000 | ... M4: =Assumptions!$B$6 -> 50000 | N4: =SUM(B4:M4) -> 600000
A5: Rent | B5: =Assumptions!$B$7 -> 30000 | C5: =Assumptions!$B$7 -> 30000 | D5: =Assumptions!$B$7 -> 30000 | E5: =Assumptions!$B$7 -> 30000 | F5: =Assumptions!$B$7 -> 30000 | G5: =Assumptions!$B$7 -> 30000 | H5: =Assumptions!$B$7 -> 30000 | I5: =Assumptions!$B$7 -> 30000 | ... M5: =Assumptions!$B$7 -> 30000 | N5: =SUM(B5:M5) -> 360000
A6: Depreciation | B6: =Assumptions!$B$7*Assumptions!$B$25 -> 3000 | C6: =Assumptions!$B$7*Assumptions!$B$25 -> 3000 | D6: =Assumptions!$B$7*Assumptions!$B$25 -> 3000 | E6: =Assumptions!$B$7*Assumptions!$B$25 -> 3000 | F6: =Assumptions!$B$7*Assumptions!$B$25 -> 3000 | G6: =Assumptions!$B$7*Assumptions!$B$25 -> 3000 | H6: =Assumptions!$B$7*Assumptions!$B$25 -> 3000 | I6: =Assumptions!$B$7*Assumptions!$B$25 -> 3000 | ... M6: =Assumptions!$B$7*Assumptions!$B$25 -> 3000 | N6: =SUM(B6:M6) -> 36000
A7: Total Cost | B7: =SUM(B2:B6) -> 1233000 | C7: =SUM(C2:C6) -> 1239000 | D7: =SUM(D2:D6) -> 1245300 | E7: =SUM(E2:E6) -> 1251915 | F7: =SUM(F2:F6) -> 1258860.8 | G7: =SUM(G2:G6) -> 1266153.8 | H7: =SUM(H2:H6) -> 1273811.5 | I7: =SUM(I2:I6) -> 1281852.1 | ... N7: =SUM(N2:N6) -> 15266055
A9: Annual Cost | B9: =SUM(B7:M7) -> 15266055
A10: Average Monthly Cost | B10: =AVERAGE(B7:M7) -> 1272171.3
A11: Months | B11: JAN | C11: FEB | D11: MAR | E11: APR | F11: MAY | G11: JUN | H11: JUL | I11: AUG | J11: SEP | K11: OCT | L11: NOV | M11: DEC
A12: Region1 | B12: =B7*25% -> 308250 | C12: =C7*25% -> 309750 | D12: =D7*25% -> 311325 | E12: =E7*25% -> 312978.75 | F12: =F7*25% -> 314715.19 | G12: =G7*25% -> 316538.45 | H12: =H7*25% -> 318452.87 | I12: =I7*25% -> 320463.01 | ... M12: =M7*25% -> 329560.18
A13: Region2 | B13: =B7*20% -> 246600 | C13: =C7*20% -> 247800 | D13: =D7*20% -> 249060 | E13: =E7*20% -> 250383 | F13: =F7*20% -> 251772.15 | G13: =G7*20% -> 253230.76 | H13: =H7*20% -> 254762.3 | I13: =I7*20% -> 256370.41 | ... M13: =M7*20% -> 263648.14
A14: Region3 | B14: =B7*18% -> 221940 | C14: =C7*18% -> 223020 | D14: =D7*18% -> 224154 | E14: =E7*18% -> 225344.7 | F14: =F7*18% -> 226594.93 | G14: =G7*18% -> 227907.68 | H14: =H7*18% -> 229286.07 | I14: =I7*18% -> 230733.37 | ... M14: =M7*18% -> 237283.33
A15: Region4 | B15: =B7*22% -> 271260 | C15: =C7*22% -> 272580 | D15: =D7*22% -> 273966 | E15: =E7*22% -> 275421.3 | F15: =F7*22% -> 276949.36 | G15: =G7*22% -> 278553.83 | H15: =H7*22% -> 280238.52 | I15: =I7*22% -> 282007.45 | ... M15: =M7*22% -> 290012.96
A16: Region5 | B16: =B7*15% -> 184950 | C16: =C7*15% -> 185850 | D16: =D7*15% -> 186795 | E16: =E7*15% -> 187787.25 | F16: =F7*15% -> 188829.11 | G16: =G7*15% -> 189923.07 | H16: =H7*15% -> 191071.72 | I16: =I7*15% -> 192277.81 | ... M16: =M7*15% -> 197736.11
A18: Months | B18: JAN | C18: FEB | D18: MAR | E18: APR | F18: MAY | G18: JUN | H18: JUL | I18: AUG | J18: SEP | K18: OCT | L18: NOV | M18: DEC
A19: BU1 | B19: =B7*20% -> 246600 | C19: =C7*20% -> 247800 | D19: =D7*20% -> 249060 | E19: =E7*20% -> 250383 | F19: =F7*20% -> 251772.15 | G19: =G7*20% -> 253230.76 | H19: =H7*20% -> 254762.3 | I19: =I7*20% -> 256370.41 | ... M19: =M7*20% -> 263648.14
A20: BU2 | B20: =B7*20% -> 246600 | C20: =C7*20% -> 247800 | D20: =D7*20% -> 249060 | E20: =E7*20% -> 250383 | F20: =F7*20% -> 251772.15 | G20: =G7*20% -> 253230.76 | H20: =H7*20% -> 254762.3 | I20: =I7*20% -> 256370.41 | ... M20: =M7*20% -> 263648.14
A21: BU3 | B21: =B7*20% -> 246600 | C21: =C7*20% -> 247800 | D21: =D7*20% -> 249060 | E21: =E7*20% -> 250383 | F21: =F7*20% -> 251772.15 | G21: =G7*20% -> 253230.76 | H21: =H7*20% -> 254762.3 | I21: =I7*20% -> 256370.41 | ... M21: =M7*20% -> 263648.14
A22: BU4 | B22: =B7*20% -> 246600 | C22: =C7*20% -> 247800 | D22: =D7*20% -> 249060 | E22: =E7*20% -> 250383 | F22: =F7*20% -> 251772.15 | G22: =G7*20% -> 253230.76 | H22: =H7*20% -> 254762.3 | I22: =I7*20% -> 256370.41 | ... M22: =M7*20% -> 263648.14
A23: BU5 | B23: =B7*20% -> 246600 | C23: =C7*20% -> 247800 | D23: =D7*20% -> 249060 | E23: =E7*20% -> 250383 | F23: =F7*20% -> 251772.15 | G23: =G7*20% -> 253230.76 | H23: =H7*20% -> 254762.3 | I23: =I7*20% -> 256370.41 | ... M23: =M7*20% -> 263648.14

Sheet P&L
A1: Months | B1: JAN | C1: FEB | D1: MAR | E1: APR | F1: MAY | G1: JUN | H1: JUL | I1: AUG | J1: SEP | K1: OCT | L1: NOV | M1: DEC
A2: Revenue | B2: =Revenue!B3 -> 1200000 | C2: =Revenue!C3 -> 1260000 | D2: =Revenue!D3 -> 1323000 | E2: =Revenue!E3 -> 1389150 | F2: =Revenue!F3 -> 1458607.5 | G2: =Revenue!G3 -> 1531537.9 | H2: =Revenue!H3 -> 1608114.8 | I2: =Revenue!I3 -> 1688520.5 | ... M2: =Revenue!M3 -> 2052407.2
A3: Total Cost | B3: =Costs!B7 -> 1233000 | C3: =Costs!C7 -> 1239000 | D3: =Costs!D7 -> 1245300 | E3: =Costs!E7 -> 1251915 | F3: =Costs!F7 -> 1258860.8 | G3: =Costs!G7 -> 1266153.8 | H3: =Costs!H7 -> 1273811.5 | I3: =Costs!I7 -> 1281852.1 | ... M3: =Costs!M7 -> 1318240.7
A4: Gross Profit | B4: =B2-B3 -> -33000 | C4: =C2-C3 -> 21000 | D4: =D2-D3 -> 77700 | E4: =E2-E3 -> 137235 | F4: =F2-F3 -> 199746.75 | G4: =G2-G3 -> 265384.09 | H4: =H2-H3 -> 334303.29 | I4: =I2-I3 -> 406668.46 | ... M4: =M2-M3 -> 734166.51
A5: EBITDA | B5: =B4 -> -33000 | C5: =C4 -> 21000 | D5: =D4 -> 77700 | E5: =E4 -> 137235 | F5: =F4 -> 199746.75 | G5: =G4 -> 265384.09 | H5: =H4 -> 334303.29 | I5: =I4 -> 406668.46 | ... M5: =M4 -> 734166.51
A6: Tax | B6: =IF(B5>0,$B$5*Assumptions!$B$24,0) -> 0 | C6: =IF(C5>0,$B$5*Assumptions!$B$24,0) -> -8250 | D6: =IF(D5>0,$B$5*Assumptions!$B$24,0) -> -8250 | E6: =IF(E5>0,$B$5*Assumptions!$B$24,0) -> -8250 | F6: =IF(F5>0,$B$5*Assumptions!$B$24,0) -> -8250 | G6: =IF(G5>0,$B$5*Assumptions!$B$24,0) -> -8250 | H6: =IF(H5>0,$B$5*Assumptions!$B$24,0) -> -8250 | I6: =IF(I5>0,$B$5*Assumptions!$B$24,0) -> -8250 | ... M6: =IF(M5>0,$B$5*Assumptions!$B$24,0) -> -8250
A7: Net Profit | B7: =B5-B6 -> -33000 | C7: =C5-C6 -> 29250 | D7: =D5-D6 -> 85950 | E7: =E5-E6 -> 145485 | F7: =F5-F6 -> 207996.75 | G7: =G5-G6 -> 273634.09 | H7: =H5-H6 -> 342553.29 | I7: =I5-I6 -> 414918.46 | ... M7: =M5-M6 -> 742416.51
A9: Total Revenue | B9: =SUM(B2:M2) -> 19100552
A10: Total Cost | B10: =SUM(B3:M3) -> 15266055
A11: Total Net Profit | B11: =SUM(B7:M7) -> 3925246.6
A13: Profit Margin | B13: =B11/B9 -> 0.20550436
A15: Note | B15: (we are assuming no extra operating expenses

Sheet CashFlow
A1: Months | B1: JAN | C1: FEB | D1: MAR | E1: APR | F1: MAY | G1: JUN | H1: JUL | I1: AUG | J1: SEP | K1: OCT | L1: NOV | M1: DEC
A2: Opening Cash | B2: 0 | C2: =B10 -> 967000 | D2: =C10 -> 979750 | E2: =D10 -> 1049200 | F2: =E10 -> 1178185 | G2: =F10 -> 1369681.8 | H2: =G10 -> 1626815.8 | I2: =H10 -> 1952869.1 | J2: =I10 -> 2351287.6 | ... M2: =L10 -> 4017830.1
A3: Cash Inflow | B3: =Revenue!B3 -> 1200000 | C3: =Revenue!C3 -> 1260000 | D3: =Revenue!D3 -> 1323000 | E3: =Revenue!E3 -> 1389150 | F3: =Revenue!F3 -> 1458607.5 | G3: =Revenue!G3 -> 1531537.9 | H3: =Revenue!H3 -> 1608114.8 | I3: =Revenue!I3 -> 1688520.5 | ... M3: =Revenue!M3 -> 2052407.2
A4: Funding Inflow | B4: =1000000 -> 1000000 | C4: =0 -> 0 | D4: =0 -> 0 | E4: =0 -> 0 | F4: =0 -> 0 | G4: =0 -> 0 | H4: =0 -> 0 | I4: =0 -> 0 | J4: =0 -> 0 | ... M4: =0 -> 0
A5: Total Inflow | B5: =B3+B4 -> 2200000 | C5: =C3+C4 -> 1260000 | D5: =D3+D4 -> 1323000 | E5: =E3+E4 -> 1389150 | F5: =F3+F4 -> 1458607.5 | G5: =G3+G4 -> 1531537.9 | H5: =H3+H4 -> 1608114.8 | I5: =I3+I4 -> 1688520.5 | ... M5: =M3+M4 -> 2052407.2
A6: Profit (after tax, from P&L) | B6: ='P&L'!B7 -> -33000 | C6: ='P&L'!C7 -> 29250 | D6: ='P&L'!D7 -> 85950 | E6: ='P&L'!E7 -> 145485 | F6: ='P&L'!F7 -> 207996.75 | G6: ='P&L'!G7 -> 273634.09 | H6: ='P&L'!H7 -> 342553.29 | I6: ='P&L'!I7 -> 414918.46 | ... M6: ='P&L'!M7 -> 742416.51
A7: Tax Paid | B7: =ABS('P&L'!B6) -> 0 | C7: =ABS('P&L'!C6) -> 8250 | D7: =ABS('P&L'!D6) -> 8250 | E7: =ABS('P&L'!E6) -> 8250 | F7: =ABS('P&L'!F6) -> 8250 | G7: =ABS('P&L'!G6) -> 8250 | H7: =ABS('P&L'!H6) -> 8250 | I7: =ABS('P&L'!I6) -> 8250 | ... M7: =ABS('P&L'!M6) -> 8250
A8: Total Outflow | B8: =Costs!B7+B7 -> 1233000 | C8: =Costs!C7+C7 -> 1247250 | D8: =Costs!D7+D7 -> 1253550 | E8: =Costs!E7+E7 -> 1260165 | F8: =Costs!F7+F7 -> 1267110.8 | G8: =Costs!G7+G7 -> 1274403.8 | H8: =Costs!H7+H7 -> 1282061.5 | I8: =Costs!I7+I7 -> 1290102.1 | ... M8: =Costs!M7+M7 -> 1326490.7
A9: Net Cash | B9: =B5-B8 -> 967000 | C9: =C5-C8 -> 12750 | D9: =D5-D8 -> 69450 | E9: =E5-E8 -> 128985 | F9: =F5-F8 -> 191496.75 | G9: =G5-G8 -> 257134.09 | H9: =H5-H8 -> 326053.29 | I9: =I5-I8 -> 398418.46 | ... M9: =M5-M8 -> 725916.51
A10: Closing Cash | B10: =B2+B9 -> 967000 | C10: =C2+C9 -> 979750 | D10: =D2+D9 -> 1049200 | E10: =E2+E9 -> 1178185 | F10: =F2+F9 -> 1369681.8 | G10: =G2+G9 -> 1626815.8 | H10: =H2+H9 -> 1952869.1 | I10: =I2+I9 -> 2351287.6 | ... M10: =M2+M9 -> 4743746.6
A11: Receivables | B11: =Revenue!B3*Assumptions!$B$22/365 -> 147945.21 | C11: =Revenue!C3*Assumptions!$B$22/365 -> 155342.47 | D11: =Revenue!D3*Assumptions!$B$22/365 -> 163109.59 | E11: =Revenue!E3*Assumptions!$B$22/365 -> 171265.07 | F11: =Revenue!F3*Assumptions!$B$22/365 -> 179828.32 | G11: =Revenue!G3*Assumptions!$B$22/365 -> 188819.74 | H11: =Revenue!H3*Assumptions!$B$22/365 -> 198260.72 | I11: =Revenue!I3*Assumptions!$B$22/365 -> 208173.76 | ... M11: =Revenue!M3*Assumptions!$B$22/365 -> 253036.51
A12: Net Cash After Working Capital | B12: =B10-B11 -> 819054.79 | C12: =C10-C11 -> 824407.53 | D12: =D10-D11 -> 886090.41 | E12: =E10-E11 -> 1006919.9 | F12: =F10-F11 -> 1189853.4 | G12: =G10-G11 -> 1437996.1 | H12: =H10-H11 -> 1754608.4 | I12: =I10-I11 -> 2143113.8 | ... M12: =M10-M11 -> 4490710.1
A13: Payables | B13: =(Costs!B3+Costs!B4+Costs!B5)*30/30 -> 200000 | C13: =(Costs!C3+Costs!C4+Costs!C5)*30/30 -> 206000 | D13: =(Costs!D3+Costs!D4+Costs!D5)*30/30 -> 212300 | E13: =(Costs!E3+Costs!E4+Costs!E5)*30/30 -> 218915 | F13: =(Costs!F3+Costs!F4+Costs!F5)*30/30 -> 225860.75 | G13: =(Costs!G3+Costs!G4+Costs!G5)*30/30 -> 233153.79 | H13: =(Costs!H3+Costs!H4+Costs!H5)*30/30 -> 240811.48 | I13: =(Costs!I3+Costs!I4+Costs!I5)*30/30 -> 248852.05 | ... M13: =(Costs!M3+Costs!M4+Costs!M5)*30/30 -> 285240.72
A15: Minimum Cash Balance | B15: =MIN(B10:M10) -> 967000
A19: Receivable Movement | B19: =B11-0 -> 147945.21 | C19: =C11-B11 -> 7397.2603 | D19: =D11-C11 -> 7767.1233 | E19: =E11-D11 -> 8155.4795 | F19: =F11-E11 -> 8563.2534 | G19: =G11-F11 -> 8991.4161 | H19: =H11-G11 -> 9440.9869 | I19: =I11-H11 -> 9913.0362 | J19: =J11-I11 -> 10408.688 | ... M19: =M11-L11 -> 12049.358
A20: Payable Movement | B20: =B13-0 -> 200000 | C20: =C13-B13 -> 6000 | D20: =D13-C13 -> 6300 | E20: =E13-D13 -> 6615 | F20: =F13-E13 -> 6945.75 | G20: =G13-F13 -> 7293.0375 | H20: =H13-G13 -> 7657.6894 | I20: =I13-H13 -> 8040.5738 | J20: =J13-I13 -> 8442.6025 | ... M20: =M13-L13 -> 9773.3678
A21: Net Working Capital | B21: =B10-(B19-B20) -> 1019054.8 | C21: =C10-(C19-C20) -> 978352.74 | D21: =D10-(D19-D20) -> 1047732.9 | E21: =E10-(E19-E20) -> 1176644.5 | F21: =F10-(F19-F20) -> 1368064.2 | G21: =G10-(G19-G20) -> 1625117.5 | H21: =H10-(H19-H20) -> 1951085.8 | I21: =I10-(I19-I20) -> 2349415.1 | ... M21: =M10-(M19-M20) -> 4741470.7

Sheet Region_BU
A1: Month | B1: Jan
A2: Region | B2: BU1 | C2: BU2 | D2: BU3 | E2: BU4 | F2: BU5 | G2: Total | H2: | Region | Total Revenue | % Contribution |
A3: Region1 | B3: {=INDEX(Revenue!$B$3:$M$3, MATCH($B$1, Revenue!$B$2:$M$2, 0)) * 0.25 * 0.2} -> 60000 | C3: {=INDEX(Revenue!$B$3:$M$3, MATCH($B$1, Revenue!$B$2:$M$2, 0)) * 0.25 * 0.2} -> 60000 | D3: {=INDEX(Revenue!$B$3:$M$3, MATCH($B$1, Revenue!$B$2:$M$2, 0)) * 0.25 * 0.2} -> 60000 | E3: {=INDEX(Revenue!$B$3:$M$3, MATCH($B$1, Revenue!$B$2:$M$2, 0)) * 0.25 * 0.2} -> 60000 | F3: {=INDEX(Revenue!$B$3:$M$3, MATCH($B$1, Revenue!$B$2:$M$2, 0)) * 0.25 * 0.2} -> 60000 | G3: =Revenue!$B$3 * Assumptions!B16 -> 300000 | H3: =G3/G8 -> 0.25
A4: Region2 | B4: {=INDEX(Revenue!$B$3:$M$3, MATCH($B$1, Revenue!$B$2:$M$2, 0)) * 0.2 * 0.2} -> 48000 | C4: {=INDEX(Revenue!$B$3:$M$3, MATCH($B$1, Revenue!$B$2:$M$2, 0)) * 0.2 * 0.2} -> 48000 | D4: {=INDEX(Revenue!$B$3:$M$3, MATCH($B$1, Revenue!$B$2:$M$2, 0)) * 0.2 * 0.2} -> 48000 | E4: {=INDEX(Revenue!$B$3:$M$3, MATCH($B$1, Revenue!$B$2:$M$2, 0)) * 0.2 * 0.2} -> 48000 | F4: {=INDEX(Revenue!$B$3:$M$3, MATCH($B$1, Revenue!$B$2:$M$2, 0)) * 0.2 * 0.2} -> 48000 | G4: =Revenue!$B$3 * Assumptions!B17 -> 240000 | H4: =G4/G8 -> 0.2
A5: Region3 | B5: {=INDEX(Revenue!$B$3:$M$3, MATCH($B$1, Revenue!$B$2:$M$2, 0)) * 0.18 * 0.2} -> 43200 | C5: {=INDEX(Revenue!$B$3:$M$3, MATCH($B$1, Revenue!$B$2:$M$2, 0)) * 0.18 * 0.2} -> 43200 | D5: {=INDEX(Revenue!$B$3:$M$3, MATCH($B$1, Revenue!$B$2:$M$2, 0)) * 0.18 * 0.2} -> 43200 | E5: {=INDEX(Revenue!$B$3:$M$3, MATCH($B$1, Revenue!$B$2:$M$2, 0)) * 0.18 * 0.2} -> 43200 | F5: {=INDEX(Revenue!$B$3:$M$3, MATCH($B$1, Revenue!$B$2:$M$2, 0)) * 0.18 * 0.2} -> 43200 | G5: =Revenue!$B$3 * Assumptions!B18 -> 216000 | H5: =G5/G8 -> 0.18
A6: Region4 | B6: {=INDEX(Revenue!$B$3:$M$3, MATCH($B$1, Revenue!$B$2:$M$2, 0)) * 0.22 * 0.2} -> 52800 | C6: {=INDEX(Revenue!$B$3:$M$3, MATCH($B$1, Revenue!$B$2:$M$2, 0)) * 0.22 * 0.2} -> 52800 | D6: {=INDEX(Revenue!$B$3:$M$3, MATCH($B$1, Revenue!$B$2:$M$2, 0)) * 0.22 * 0.2} -> 52800 | E6: {=INDEX(Revenue!$B$3:$M$3, MATCH($B$1, Revenue!$B$2:$M$2, 0)) * 0.22 * 0.2} -> 52800 | F6: {=INDEX(Revenue!$B$3:$M$3, MATCH($B$1, Revenue!$B$2:$M$2, 0)) * 0.22 * 0.2} -> 52800 | G6: =Revenue!$B$3 * Assumptions!B19 -> 264000 | H6: =G6/G8 -> 0.22
A7: Region5 | B7: {=INDEX(Revenue!$B$3:$M$3, MATCH($B$1, Revenue!$B$2:$M$2, 0)) * 0.15 * 0.2} -> 36000 | C7: {=INDEX(Revenue!$B$3:$M$3, MATCH($B$1, Revenue!$B$2:$M$2, 0)) * 0.15 * 0.2} -> 36000 | D7: {=INDEX(Revenue!$B$3:$M$3, MATCH($B$1, Revenue!$B$2:$M$2, 0)) * 0.15 * 0.2} -> 36000 | E7: {=INDEX(Revenue!$B$3:$M$3, MATCH($B$1, Revenue!$B$2:$M$2, 0)) * 0.15 * 0.2} -> 36000 | F7: {=INDEX(Revenue!$B$3:$M$3, MATCH($B$1, Revenue!$B$2:$M$2, 0)) * 0.15 * 0.2} -> 36000 | G7: =Revenue!$B$3 * Assumptions!B20 -> 180000 | H7: =G7/G8 -> 0.15
A8: Total | B8: =SUM(B3:B7) -> 240000 | C8: =SUM(C3:C7) -> 240000 | D8: =SUM(D3:D7) -> 240000 | E8: =SUM(E3:E7) -> 240000 | F8: =SUM(F3:F7) -> 240000 | G8: =SUM(G3:G7) -> 1200000 | H8: =SUM(H3:H7) -> 1
A10: Total January revenue | B10: {=INDEX(Revenue!$B$3:$M$3, MATCH($B$1, Revenue!$B$2:$M$2, 0))} -> 1200000

Sheet Variance
A1: Month | B1: Budget Revenue | C1: Actual Revenue | D1: Variance | E1: % Variance | F1: Reason
A2: JAN | B2: =Revenue!B3 -> 1200000 | C2: 1248000 | D2: =C2-B2 -> 48000 | E2: =(C2-B2)/B2 -> 0.04 | F2: Strong start to the year driven by early deal closures and improved sales productivity.
A3: FEB | B3: =Revenue!C3 -> 1260000 | C3: 1234800 | D3: =C3-B3 -> -25200 | E3: =(C3-B3)/B3 -> -0.02 | F3: Slight decline due to delay in deal closures and lower-than-expected conversion rate.
A4: MAR | B4: =Revenue!D3 -> 1323000 | C4: 1243620 | D4: =C4-B4 -> -79380 | E4: =(C4-B4)/B4 -> -0.06 | F4: Impact of seasonal slowdown and weaker sales pipeline conversion towards quarter end.
A5: APR | B5: =Revenue!E3 -> 1389150 | C5: 1389150 | D5: =C5-B5 -> 0 | E5: =(C5-B5)/B5 -> 0 | F5: Performance in line with budget, indicating stable execution and accurate forecasting.
A6: MAY | B6: =Revenue!F3 -> 1458607.5 | C6: 1341918.9 | D6: =C6-B6 -> -116688.6 | E6: =(C6-B6)/B6 -> -0.08 | F6: Underperformance due to delayed client decisions and slower deal closures.
A7: JUN | B7: =Revenue!G3 -> 1531537.9 | C7: 1485591.7 | D7: =C7-B7 -> -45946.136 | E7: =(C7-B7)/B7 -> -0.03 | F7: Minor shortfall due to moderate pipeline conversion despite steady deal flow.
A8: JUL | B8: =Revenue!H3 -> 1608114.8 | C8: 1704601.7 | D8: =C8-B8 -> 96486.886 | E8: =(C8-B8)/B8 -> 0.06 | F8: Higher-than-expected revenue driven by strong deal closures and improved sales execution.
A9: AUG | B9: =Revenue!I3 -> 1688520.5 | C9: 1756061.3 | D9: =C9-B9 -> 67540.82 | E9: =(C9-B9)/B9 -> 0.04 | F9: Continued momentum from previous month with better pipeline conversion and productivity.
A10: SEP | B10: =Revenue!J3 -> 1772946.5 | C10: 1932511.7 | D10: =C10-B10 -> 159565.19 | E10: =(C10-B10)/B10 -> 0.09 | F10: Peak performance driven by closing of high-value deals and strong sales efficiency.
A11: OCT | B11: =Revenue!K3 -> 1861593.9 | C11: 1768514.2 | D11: =C11-B11 -> -93079.693 | E11: =(C11-B11)/B11 -> -0.05 | F11: Decline due to festive season impact and reduced working days affecting sales activity.
A12: NOV | B12: =Revenue!L3 -> 1954673.6 | C12: 1935126.8 | D12: =C12-B12 -> -19546.736 | E12: =(C12-B12)/B12 -> -0.01 | F12: Slight underperformance due to slower deal pipeline and cautious client spending.
A13: DEC | B13: =Revenue!M3 -> 2052407.2 | C13: 2216599.8 | D13: =C13-B13 -> 164192.58 | E13: =(C13-B13)/B13 -> 0.08 | F13: Strong year-end push with accelerated deal closures and achievement of annual targets.

Sheet Sales_Performance
A1: Sales Exec | B1: Region | C1: Target Revenue | D1: Actual Revenue | E1: Variance | F1: % Variance | G1: Region No
A2: SE1 | B2: ="Region"&INT((ROW()-2)/10)+1 -> Region1 | C2: {=INDEX(Region_BU!$G$3:$G$7, G2)/10} -> 30000 | D2: 32400 | E2: =D2-C2 -> 2400 | F2: =E2/C2 -> 0.08 | G2: =RIGHT(B2,1) -> 1 | J2: Top performers → Green
A3: SE2 | B3: ="Region"&INT((ROW()-2)/10)+1 -> Region1 | C3: {=INDEX(Region_BU!$G$3:$G$7, G3)/10} -> 30000 | D3: 28800 | E3: =D3-C3 -> -1200 | F3: =E3/C3 -> -0.04 | G3: =RIGHT(B3,1) -> 1 | J3: Negative variance → Red
A4: SE3 | B4: ="Region"&INT((ROW()-2)/10)+1 -> Region1 | C4: {=INDEX(Region_BU!$G$3:$G$7, G4)/10} -> 30000 | D4: 29100 | E4: =D4-C4 -> -900 | F4: =E4/C4 -> -0.03 | G4: =RIGHT(B4,1) -> 1
A5: SE4 | B5: ="Region"&INT((ROW()-2)/10)+1 -> Region1 | C5: {=INDEX(Region_BU!$G$3:$G$7, G5)/10} -> 30000 | D5: 27600 | E5: =D5-C5 -> -2400 | F5: =E5/C5 -> -0.08 | G5: =RIGHT(B5,1) -> 1
A6: SE5 | B6: ="Region"&INT((ROW()-2)/10)+1 -> Region1 | C6: {=INDEX(Region_BU!$G$3:$G$7, G6)/10} -> 30000 | D6: 27600 | E6: =D6-C6 -> -2400 | F6: =E6/C6 -> -0.08 | G6: =RIGHT(B6,1) -> 1
A7: SE6 | B7: ="Region"&INT((ROW()-2)/10)+1 -> Region1 | C7: {=INDEX(Region_BU!$G$3:$G$7, G7)/10} -> 30000 | D7: 32700 | E7: =D7-C7 -> 2700 | F7: =E7/C7 -> 0.09 | G7: =RIGHT(B7,1) -> 1
A8: SE7 | B8: ="Region"&INT((ROW()-2)/10)+1 -> Region1 | C8: {=INDEX(Region_BU!$G$3:$G$7, G8)/10} -> 30000 | D8: 27300 | E8: =D8-C8 -> -2700 | F8: =E8/C8 -> -0.09 | G8: =RIGHT(B8,1) -> 1
A9: SE8 | B9: ="Region"&INT((ROW()-2)/10)+1 -> Region1 | C9: {=INDEX(Region_BU!$G$3:$G$7, G9)/10} -> 30000 | D9: 28500 | E9: =D9-C9 -> -1500 | F9: =E9/C9 -> -0.05 | G9: =RIGHT(B9,1) -> 1
A10: SE9 | B10: ="Region"&INT((ROW()-2)/10)+1 -> Region1 | C10: {=INDEX(Region_BU!$G$3:$G$7, G10)/10} -> 30000 | D10: 29700 | E10: =D10-C10 -> -300 | F10: =E10/C10 -> -0.01 | G10: =RIGHT(B10,1) -> 1
A11: SE10 | B11: ="Region"&INT((ROW()-2)/10)+1 -> Region1 | C11: {=INDEX(Region_BU!$G$3:$G$7, G11)/10} -> 30000 | D11: 33000 | E11: =D11-C11 -> 3000 | F11: =E11/C11 -> 0.1 | G11: =RIGHT(B11,1) -> 1
A12: SE11 | B12: ="Region"&INT((ROW()-2)/10)+1 -> Region2 | C12: {=INDEX(Region_BU!$G$3:$G$7, G12)/10} -> 24000 | D12: 24240 | E12: =D12-C12 -> 240 | F12: =E12/C12 -> 0.01 | G12: =RIGHT(B12,1) -> 2
A13: SE12 | B13: ="Region"&INT((ROW()-2)/10)+1 -> Region2 | C13: {=INDEX(Region_BU!$G$3:$G$7, G13)/10} -> 24000 | D13: 26400 | E13: =D13-C13 -> 2400 | F13: =E13/C13 -> 0.1 | G13: =RIGHT(B13,1) -> 2
A14: SE13 | B14: ="Region"&INT((ROW()-2)/10)+1 -> Region2 | C14: {=INDEX(Region_BU!$G$3:$G$7, G14)/10} -> 24000 | D14: 24240 | E14: =D14-C14 -> 240 | F14: =E14/C14 -> 0.01 | G14: =RIGHT(B14,1) -> 2
A15: SE14 | B15: ="Region"&INT((ROW()-2)/10)+1 -> Region2 | C15: {=INDEX(Region_BU!$G$3:$G$7, G15)/10} -> 24000 | D15: 24000 | E15: =D15-C15 -> 0 | F15: =E15/C15 -> 0 | G15: =RIGHT(B15,1) -> 2
... A51: SE50 | B51: ="Region"&INT((ROW()-2)/10)+1 -> Region5 | C51: {=INDEX(Region_BU!$G$3:$G$7, G51)/10} -> 18000 | D51: 18360 | E51: =D51-C51 -> 360 | F51: =E51/C51 -> 0.02 | G51: =RIGHT(B51,1) -> 5

Sheet Regional_Heads
A1: Regional Head | B1: Region | C1: Target Revenue | D1: Actual Revenue | E1: Variance | F1: % Variance | G1: Region No
A2: RH1 | B2: ="Region"&ROUNDUP(ROW(A1)/2,0) -> Region1 | C2: {=INDEX(Region_BU!$G$3:$G$7, VALUE(G2))/2} -> 150000 | D2: =SUMIFS(Sales_Performance!D:D, Sales_Performance!B:B, B2)/2 -> 148350 | E2: =D2-C2 -> -1650 | F2: =E2/C2 -> -0.011 | G2: =RIGHT(B2,1) -> 1 | I2: Top performers → Green
A3: RH2 | B3: ="Region"&ROUNDUP(ROW(A2)/2,0) -> Region1 | C3: {=INDEX(Region_BU!$G$3:$G$7, VALUE(G3))/2} -> 150000 | D3: =SUMIFS(Sales_Performance!D:D, Sales_Performance!B:B, B3)/2 -> 148350 | E3: =D3-C3 -> -1650 | F3: =E3/C3 -> -0.011 | G3: =RIGHT(B3,1) -> 1 | I3: Negative variance → Red
A4: RH3 | B4: ="Region"&ROUNDUP(ROW(A3)/2,0) -> Region2 | C4: {=INDEX(Region_BU!$G$3:$G$7, VALUE(G4))/2} -> 120000 | D4: =SUMIFS(Sales_Performance!D:D, Sales_Performance!B:B, B4)/2 -> 124080 | E4: =D4-C4 -> 4080 | F4: =E4/C4 -> 0.034 | G4: =RIGHT(B4,1) -> 2
A5: RH4 | B5: ="Region"&ROUNDUP(ROW(A4)/2,0) -> Region2 | C5: {=INDEX(Region_BU!$G$3:$G$7, VALUE(G5))/2} -> 120000 | D5: =SUMIFS(Sales_Performance!D:D, Sales_Performance!B:B, B5)/2 -> 124080 | E5: =D5-C5 -> 4080 | F5: =E5/C5 -> 0.034 | G5: =RIGHT(B5,1) -> 2
A6: RH5 | B6: ="Region"&ROUNDUP(ROW(A5)/2,0) -> Region3 | C6: {=INDEX(Region_BU!$G$3:$G$7, VALUE(G6))/2} -> 108000 | D6: =SUMIFS(Sales_Performance!D:D, Sales_Performance!B:B, B6)/2 -> 105408 | E6: =D6-C6 -> -2592 | F6: =E6/C6 -> -0.024 | G6: =RIGHT(B6,1) -> 3
A7: RH6 | B7: ="Region"&ROUNDUP(ROW(A6)/2,0) -> Region3 | C7: {=INDEX(Region_BU!$G$3:$G$7, VALUE(G7))/2} -> 108000 | D7: =SUMIFS(Sales_Performance!D:D, Sales_Performance!B:B, B7)/2 -> 105408 | E7: =D7-C7 -> -2592 | F7: =E7/C7 -> -0.024 | G7: =RIGHT(B7,1) -> 3
A8: RH7 | B8: ="Region"&ROUNDUP(ROW(A7)/2,0) -> Region4 | C8: {=INDEX(Region_BU!$G$3:$G$7, VALUE(G8))/2} -> 132000 | D8: =SUMIFS(Sales_Performance!D:D, Sales_Performance!B:B, B8)/2 -> 134376 | E8: =D8-C8 -> 2376 | F8: =E8/C8 -> 0.018 | G8: =RIGHT(B8,1) -> 4
A9: RH8 | B9: ="Region"&ROUNDUP(ROW(A8)/2,0) -> Region4 | C9: {=INDEX(Region_BU!$G$3:$G$7, VALUE(G9))/2} -> 132000 | D9: =SUMIFS(Sales_Performance!D:D, Sales_Performance!B:B, B9)/2 -> 134376 | E9: =D9-C9 -> 2376 | F9: =E9/C9 -> 0.018 | G9: =RIGHT(B9,1) -> 4
A10: RH9 | B10: ="Region"&ROUNDUP(ROW(A9)/2,0) -> Region5 | C10: {=INDEX(Region_BU!$G$3:$G$7, VALUE(G10))/2} -> 90000 | D10: =SUMIFS(Sales_Performance!D:D, Sales_Performance!B:B, B10)/2 -> 89910 | E10: =D10-C10 -> -90 | F10: =E10/C10 -> -0.001 | G10: =RIGHT(B10,1) -> 5
A11: RH10 | B11: ="Region"&ROUNDUP(ROW(A10)/2,0) -> Region5 | C11: {=INDEX(Region_BU!$G$3:$G$7, VALUE(G11))/2} -> 90000 | D11: =SUMIFS(Sales_Performance!D:D, Sales_Performance!B:B, B11)/2 -> 89910 | E11: =D11-C11 -> -90 | F11: =E11/C11 -> -0.001 | G11: =RIGHT(B11,1) -> 5

Sheet Balance_Sheet
A1: Particulars | B1: Year End
A2: ASSETS | H2: Gross PPE = Annual Depreciation / Depreciation Rate
A3: Cash | B3: =CashFlow!M12 -> 4490710.1 | H3: Gross PPE | I3: =36000/10% -> 360000
A4: Accounts Receivable | B4: =SUM(Revenue!B3:M3)*10% -> 1910055.2
A5: Total Assets | B5: =B4+B3 -> 6400765.3
A6: LIABILITIES & EQUITY
A7: Equity Capital | B7: =B5 - B8 -> 2566268.7
A8: Retained Earnings | B8: =SUM('P&L'!B4:M4) -> 3834496.6
A9: Total Liabilities & Equity | B9: =B8+B7 -> 6400765.3
A12: Gross PPE | B12: 360000
A13: Accumulated Depreciation | B13: =Costs!N6 -> 36000
A14: Net PPE | B14: =B12-B13 -> 324000
A15: Accounts Payable | B15: =(Costs!M3+Costs!M4+Costs!M5)*30/30 -> 285240.72
A16: Opening RE | B16: 0
A17: Add Net Profit | B17: ='P&L'!B11 -> 3925246.6
A18: Closing RE | B18: =B16+B17 -> 3925246.6

Sheet Financial Dashboard
F1: Financial Dashboard – IT Company Budget
A5: KPI | B5: Value
A6: Total Revenue | B6: =SUM(Revenue!B3:M3) -> 19100552
A7: Total Cost | B7: =SUM(Costs!B7:M7) -> 15266055
A8: Total Profit | B8: =SUM('P&L'!B4:M4) -> 3834496.6
A9: Avg Monthly Revenue | B9: =AVERAGE(Revenue!B3:M3) -> 1591712.7
A10: Profit Margin | B10: =B8/B6 -> 0.20075319

Sheet Insights
A1: Insights:
A2: 1. Revenue Insights
A4: The company shows a consistent monthly revenue growth of 5% under Base Case.
A5: Revenue contribution is diversified across regions.
A6: Region1 contributes 25% (highest)
A7: Region5 contributes 15% (lowest)
A8: Business Units are equally structured (20% each), ensuring balanced BU-level visibility.
A9: Scenario Manager allows the company to simulate Worst (3%), Base (5%), and Best Case (7%) revenue growth.
A10: Under Worst Case, revenue growth slows significantly due to weaker demand.
A11: Under Best Case, strong pipeline and better conversion drive accelerated growth.
A13: 2. Profitability Insights
A15: EBITDA increases consistently across the year under Base Case assumptions.
... A75: IMP Note:- The model includes scenario dropdowns (Worst, Base, Best) in Revenue Sheet and month selectors Drop down in Region_BU sheets that dynamically update Revenue, Region Allocation, BU Allocation, P&L, Cash Flow and Balance Sheet.
